Workbook

Sheet 1 Accident Data
B1: 1 Accident locations
B2: 30 injury or fatal accidents on a 100 km road | September
B5: No. | C5: Location (km) | E5: Statistical summary | F5: Value | H5: Interval (km) | I5: Frequency | J5: Relative | K5: Cumulative
B6: 1 | C6: 88.3 | E6: Count | F6: =COUNT(C6:C35) -> 30 | H6: 0-10 | I6: =COUNTIFS($C$6:$C$35,">="&0,$C$6:$C$35,"<"&10) -> 2 | J6: =I6/$F$6 -> 0.066666667 | K6: =SUM($J$6:J6) -> 0.066666667
B7: 2 | C7: 40.7 | E7: Sum (km) | F7: =SUM(C6:C35) -> 1661.9 | H7: 10-20 | I7: =COUNTIFS($C$6:$C$35,">="&10,$C$6:$C$35,"<"&20) -> 1 | J7: =I7/$F$6 -> 0.033333333 | K7: =SUM($J$6:J7) -> 0.1
B8: 3 | C8: 36.3 | E8: Mean (km) | F8: =AVERAGE(C6:C35) -> 55.396667 | H8: 20-30 | I8: =COUNTIFS($C$6:$C$35,">="&20,$C$6:$C$35,"<"&30) -> 6 | J8: =I8/$F$6 -> 0.2 | K8: =SUM($J$6:J8) -> 0.3
B9: 4 | C9: 27.3 | E9: Median (km) | F9: =MEDIAN(C6:C35) -> 53.95 | H9: 30-40 | I9: =COUNTIFS($C$6:$C$35,">="&30,$C$6:$C$35,"<"&40) -> 3 | J9: =I9/$F$6 -> 0.1 | K9: =SUM($J$6:J9) -> 0.4
B10: 5 | C10: 36.8 | E10: Mode (km) | F10: =MODE(C6:C35) -> 27.3 | H10: 40-50 | I10: =COUNTIFS($C$6:$C$35,">="&40,$C$6:$C$35,"<"&50) -> 3 | J10: =I10/$F$6 -> 0.1 | K10: =SUM($J$6:J10) -> 0.5
B11: 6 | C11: 91.7 | E11: Minimum (km) | F11: =MIN(C6:C35) -> 6 | H11: 50-60 | I11: =COUNTIFS($C$6:$C$35,">="&50,$C$6:$C$35,"<"&60) -> 0 | J11: =I11/$F$6 -> 0 | K11: =SUM($J$6:J11) -> 0.5
B12: 7 | C12: 67.3 | E12: Maximum (km) | F12: =MAX(C6:C35) -> 99.7 | H12: 60-70 | I12: =COUNTIFS($C$6:$C$35,">="&60,$C$6:$C$35,"<"&70) -> 3 | J12: =I12/$F$6 -> 0.1 | K12: =SUM($J$6:J12) -> 0.6
B13: 8 | C13: 7 | E13: Range (km) | F13: =F12-F11 -> 93.7 | H13: 70-80 | I13: =COUNTIFS($C$6:$C$35,">="&70,$C$6:$C$35,"<"&80) -> 3 | J13: =I13/$F$6 -> 0.1 | K13: =SUM($J$6:J13) -> 0.7
B14: 9 | C14: 45.2 | E14: Q1 (km) | F14: =QUARTILE(C6:C35,1) -> 27.3 | H14: 80-90 | I14: =COUNTIFS($C$6:$C$35,">="&80,$C$6:$C$35,"<"&90) -> 4 | J14: =I14/$F$6 -> 0.13333333 | K14: =SUM($J$6:J14) -> 0.83333333
B15: 10 | C15: 23.3 | E15: Q3 (km) | F15: =QUARTILE(C6:C35,3) -> 87.5 | H15: 90-100 | I15: =COUNTIFS($C$6:$C$35,">="&90,$C$6:$C$35,"<"&100) -> 5 | J15: =I15/$F$6 -> 0.16666667 | K15: =SUM($J$6:J15) -> 1
B16: 11 | C16: 98.8 | E16: IQR (km) | F16: =F15-F14 -> 60.2 | H16: Total | I16: =SUM(I6:I15) -> 30 | J16: =SUM(J6:J15) -> 1
B17: 12 | C17: 90.1 | E17: Sample variance | F17: =VAR(C6:C35) -> 953.9493
B18: 13 | C18: 17.2 | E18: Sample SD (km) | F18: =STDEV(C6:C35) -> 30.88607
B19: 14 | C19: 23.7 | E19: CV | F19: =F18/F8 -> 0.55754383
B20: 15 | C20: 97.4 | E20: Skewness | F20: =SKEW(C6:C35) -> -0.021307115
B21: 16 | C21: 32.4 | E21: Excess kurtosis | F21: =KURT(C6:C35) -> -1.5288123
B22: 17 | C22: 87.8
B23: 18 | C23: 69.8
B24: 19 | C24: 62.6
B25: 20 | C25: 99.7
B26: 21 | C26: 20.6
B27: 22 | C27: 73.1
B28: 23 | C28: 21.6
B29: 24 | C29: 6
B30: 25 | C30: 45.3
B31: 26 | C31: 76.6
B32: 27 | C32: 73.2
B33: 28 | C33: 27.3
... B35: 30 | C35: 87.2
B37: Source: Pem-Sim Kelas E.pdf, p. 1 (embedded data image). Sample statistics use n - 1; quartiles use Excel QUARTILE inclusive method.

Sheet 1 KS Test
B1: 1 Kolmogorov-Smirnov test
B2: H0: accident location follows Uniform(0, 100 km) | two-sided test, alpha = 0.05
B6: Rank i | C6: Sorted x (km) | D6: F0(x) = x/100 | E6: (i-1)/n | F6: i/n | G6: Local D | I6: Test result | J6: Value
B7: 1 | C7: =SMALL('1 Accident Data'!$C$6:$C$35,B7) -> 6 | D7: =C7/100 -> 0.06 | E7: =(B7-1)/$J$7 -> 0 | F7: =B7/$J$7 -> 0.033333333 | G7: =MAX(D7-E7,F7-D7) -> 0.06 | I7: n | J7: ='1 Accident Data'!F6 -> 30
B8: 2 | C8: =SMALL('1 Accident Data'!$C$6:$C$35,B8) -> 7 | D8: =C8/100 -> 0.07 | E8: =(B8-1)/$J$7 -> 0.033333333 | F8: =B8/$J$7 -> 0.066666667 | G8: =MAX(D8-E8,F8-D8) -> 0.036666667 | I8: Alpha | J8: 0.05
B9: 3 | C9: =SMALL('1 Accident Data'!$C$6:$C$35,B9) -> 17.2 | D9: =C9/100 -> 0.172 | E9: =(B9-1)/$J$7 -> 0.066666667 | F9: =B9/$J$7 -> 0.1 | G9: =MAX(D9-E9,F9-D9) -> 0.10533333 | I9: D statistic | J9: =MAX(G7:G36) -> 0.172
B10: 4 | C10: =SMALL('1 Accident Data'!$C$6:$C$35,B10) -> 20.6 | D10: =C10/100 -> 0.206 | E10: =(B10-1)/$J$7 -> 0.1 | F10: =B10/$J$7 -> 0.13333333 | G10: =MAX(D10-E10,F10-D10) -> 0.106 | I10: Exact D critical | J10: 0.24170347
B11: 5 | C11: =SMALL('1 Accident Data'!$C$6:$C$35,B11) -> 21.6 | D11: =C11/100 -> 0.216 | E11: =(B11-1)/$J$7 -> 0.13333333 | F11: =B11/$J$7 -> 0.16666667 | G11: =MAX(D11-E11,F11-D11) -> 0.082666667 | I11: Decision | J11: =IF(J9>J10,"Reject H0","Do not reject H0") -> Do not reject H0
B12: 6 | C12: =SMALL('1 Accident Data'!$C$6:$C$35,B12) -> 23.3 | D12: =C12/100 -> 0.233 | E12: =(B12-1)/$J$7 -> 0.16666667 | F12: =B12/$J$7 -> 0.2 | G12: =MAX(D12-E12,F12-D12) -> 0.066333333 | I12: Conclusion | J12: =IF(J9>J10,"Non-uniform evidence","Uniform fit plausible") -> Uniform fit plausible
B13: 7 | C13: =SMALL('1 Accident Data'!$C$6:$C$35,B13) -> 23.7 | D13: =C13/100 -> 0.237 | E13: =(B13-1)/$J$7 -> 0.2 | F13: =B13/$J$7 -> 0.23333333 | G13: =MAX(D13-E13,F13-D13) -> 0.037
B14: 8 | C14: =SMALL('1 Accident Data'!$C$6:$C$35,B14) -> 27.3 | D14: =C14/100 -> 0.273 | E14: =(B14-1)/$J$7 -> 0.23333333 | F14: =B14/$J$7 -> 0.26666667 | G14: =MAX(D14-E14,F14-D14) -> 0.039666667
B15: 9 | C15: =SMALL('1 Accident Data'!$C$6:$C$35,B15) -> 27.3 | D15: =C15/100 -> 0.273 | E15: =(B15-1)/$J$7 -> 0.26666667 | F15: =B15/$J$7 -> 0.3 | G15: =MAX(D15-E15,F15-D15) -> 0.027 | I15: D is the maximum vertical difference between empirical and Uniform(0,100) CDFs. Reject H0 only when D exceeds the exact 5% critical value.
B16: 10 | C16: =SMALL('1 Accident Data'!$C$6:$C$35,B16) -> 32.4 | D16: =C16/100 -> 0.324 | E16: =(B16-1)/$J$7 -> 0.3 | F16: =B16/$J$7 -> 0.33333333 | G16: =MAX(D16-E16,F16-D16) -> 0.024
B17: 11 | C17: =SMALL('1 Accident Data'!$C$6:$C$35,B17) -> 36.3 | D17: =C17/100 -> 0.363 | E17: =(B17-1)/$J$7 -> 0.33333333 | F17: =B17/$J$7 -> 0.36666667 | G17: =MAX(D17-E17,F17-D17) -> 0.029666667
B18: 12 | C18: =SMALL('1 Accident Data'!$C$6:$C$35,B18) -> 36.8 | D18: =C18/100 -> 0.368 | E18: =(B18-1)/$J$7 -> 0.36666667 | F18: =B18/$J$7 -> 0.4 | G18: =MAX(D18-E18,F18-D18) -> 0.032
B19: 13 | C19: =SMALL('1 Accident Data'!$C$6:$C$35,B19) -> 40.7 | D19: =C19/100 -> 0.407 | E19: =(B19-1)/$J$7 -> 0.4 | F19: =B19/$J$7 -> 0.43333333 | G19: =MAX(D19-E19,F19-D19) -> 0.026333333
B20: 14 | C20: =SMALL('1 Accident Data'!$C$6:$C$35,B20) -> 45.2 | D20: =C20/100 -> 0.452 | E20: =(B20-1)/$J$7 -> 0.43333333 | F20: =B20/$J$7 -> 0.46666667 | G20: =MAX(D20-E20,F20-D20) -> 0.018666667
B21: 15 | C21: =SMALL('1 Accident Data'!$C$6:$C$35,B21) -> 45.3 | D21: =C21/100 -> 0.453 | E21: =(B21-1)/$J$7 -> 0.46666667 | F21: =B21/$J$7 -> 0.5 | G21: =MAX(D21-E21,F21-D21) -> 0.047
B22: 16 | C22: =SMALL('1 Accident Data'!$C$6:$C$35,B22) -> 62.6 | D22: =C22/100 -> 0.626 | E22: =(B22-1)/$J$7 -> 0.5 | F22: =B22/$J$7 -> 0.53333333 | G22: =MAX(D22-E22,F22-D22) -> 0.126
B23: 17 | C23: =SMALL('1 Accident Data'!$C$6:$C$35,B23) -> 67.3 | D23: =C23/100 -> 0.673 | E23: =(B23-1)/$J$7 -> 0.53333333 | F23: =B23/$J$7 -> 0.56666667 | G23: =MAX(D23-E23,F23-D23) -> 0.13966667
B24: 18 | C24: =SMALL('1 Accident Data'!$C$6:$C$35,B24) -> 69.8 | D24: =C24/100 -> 0.698 | E24: =(B24-1)/$J$7 -> 0.56666667 | F24: =B24/$J$7 -> 0.6 | G24: =MAX(D24-E24,F24-D24) -> 0.13133333
B25: 19 | C25: =SMALL('1 Accident Data'!$C$6:$C$35,B25) -> 73.1 | D25: =C25/100 -> 0.731 | E25: =(B25-1)/$J$7 -> 0.6 | F25: =B25/$J$7 -> 0.63333333 | G25: =MAX(D25-E25,F25-D25) -> 0.131
B26: 20 | C26: =SMALL('1 Accident Data'!$C$6:$C$35,B26) -> 73.2 | D26: =C26/100 -> 0.732 | E26: =(B26-1)/$J$7 -> 0.63333333 | F26: =B26/$J$7 -> 0.66666667 | G26: =MAX(D26-E26,F26-D26) -> 0.098666667
B27: 21 | C27: =SMALL('1 Accident Data'!$C$6:$C$35,B27) -> 76.6 | D27: =C27/100 -> 0.766 | E27: =(B27-1)/$J$7 -> 0.66666667 | F27: =B27/$J$7 -> 0.7 | G27: =MAX(D27-E27,F27-D27) -> 0.099333333
... B36: 30 | C36: =SMALL('1 Accident Data'!$C$6:$C$35,B36) -> 99.7 | D36: =C36/100 -> 0.997 | E36: =(B36-1)/$J$7 -> 0.96666667 | F36: =B36/$J$7 -> 1 | G36: =MAX(D36-E36,F36-D36) -> 0.030333333
B38: Data: Pem-Sim Kelas E.pdf, p. 1. Method: Law, Simulation Modeling and Analysis, 5th ed., ch. 6. Exact critical value: SciPy kstwo, n = 30.

Sheet 2 Time Data
B1: 2 Employee recording times
B2: 50 employee observations | time in minutes
B5: Employee | C5: Time (min) | E5: Employee | F5: Time (min) | H5: Statistical summary | I5: Value
B6: 1 | C6: 1.88 | E6: 26 | F6: 0.04 | H6: Count | I6: =COUNT(T6:T55) -> 50 | T6: =C6 -> 1.88
B7: 2 | C7: 0.54 | E7: 27 | F7: 1.49 | H7: Sum (min) | I7: =SUM(T6:T55) -> 60.3 | T7: =C7 -> 0.54
B8: 3 | C8: 1.9 | E8: 28 | F8: 0.66 | H8: Mean (min) | I8: =AVERAGE(T6:T55) -> 1.206 | T8: =C8 -> 1.9
B9: 4 | C9: 0.15 | E9: 29 | F9: 2.03 | H9: Median (min) | I9: =MEDIAN(T6:T55) -> 0.795 | T9: =C9 -> 0.15
B10: 5 | C10: 0.02 | E10: 30 | F10: 1 | H10: One mode (min) | I10: =MODE(T6:T55) -> 0.53 | T10: =C10 -> 0.02
B11: 6 | C11: 2.81 | E11: 31 | F11: 0.39 | H11: Minimum (min) | I11: =MIN(T6:T55) -> 0.01 | T11: =C11 -> 2.81
B12: 7 | C12: 1.5 | E12: 32 | F12: 0.34 | H12: Maximum (min) | I12: =MAX(T6:T55) -> 5.5 | T12: =C12 -> 1.5
B13: 8 | C13: 0.53 | E13: 33 | F13: 0.01 | H13: Range (min) | I13: =I12-I11 -> 5.49 | T13: =C13 -> 0.53
B14: 9 | C14: 2.62 | E14: 34 | F14: 0.1 | H14: Q1 (min) | I14: =QUARTILE(T6:T55,1) -> 0.3525 | T14: =C14 -> 2.62
B15: 10 | C15: 2.67 | E15: 35 | F15: 1.1 | H15: Q3 (min) | I15: =QUARTILE(T6:T55,3) -> 1.7825 | T15: =C15 -> 2.67
B16: 11 | C16: 3.53 | E16: 36 | F16: 0.24 | H16: IQR (min) | I16: =I15-I14 -> 1.43 | T16: =C16 -> 3.53
B17: 12 | C17: 0.53 | E17: 37 | F17: 0.26 | H17: Sample variance | I17: =VAR(T6:T55) -> 1.6055755 | T17: =C17 -> 0.53
B18: 13 | C18: 1.8 | E18: 38 | F18: 0.45 | H18: Sample SD (min) | I18: =STDEV(T6:T55) -> 1.2671131 | T18: =C18 -> 1.8
B19: 14 | C19: 0.79 | E19: 39 | F19: 0.17 | H19: CV | I19: =I18/I8 -> 1.0506742 | T19: =C19 -> 0.79
B20: 15 | C20: 0.21 | E20: 40 | F20: 4.29 | H20: Skewness | I20: =SKEW(T6:T55) -> 1.727157 | T20: =C20 -> 0.21
B21: 16 | C21: 0.8 | E21: 41 | F21: 0.8 | H21: Excess kurtosis | I21: =KURT(T6:T55) -> 2.9370388 | T21: =C21 -> 0.8
B22: 17 | C22: 0.26 | E22: 42 | F22: 5.5 | T22: =C22 -> 0.26
B23: 18 | C23: 0.63 | E23: 43 | F23: 4.91 | H23: Interval (min) | I23: Frequency | T23: =C23 -> 0.63
B24: 19 | C24: 0.36 | E24: 44 | F24: 0.35 | H24: 0-1 | I24: =COUNTIFS($T$6:$T$55,">="&0,$T$6:$T$55,"<"&1) -> 29 | T24: =C24 -> 0.36
B25: 20 | C25: 2.03 | E25: 45 | F25: 0.36 | H25: 1-2 | I25: =COUNTIFS($T$6:$T$55,">="&1,$T$6:$T$55,"<"&2) -> 11 | T25: =C25 -> 2.03
B26: 21 | C26: 1.42 | E26: 46 | F26: 0.9 | H26: 2-3 | I26: =COUNTIFS($T$6:$T$55,">="&2,$T$6:$T$55,"<"&3) -> 6 | T26: =C26 -> 1.42
B27: 22 | C27: 1.28 | E27: 47 | F27: 1.03 | H27: 3-4 | I27: =COUNTIFS($T$6:$T$55,">="&3,$T$6:$T$55,"<"&4) -> 1 | T27: =C27 -> 1.28
B28: 23 | C28: 0.82 | E28: 48 | F28: 1.73 | H28: 4-5 | I28: =COUNTIFS($T$6:$T$55,">="&4,$T$6:$T$55,"<"&5) -> 2 | T28: =C28 -> 0.82
B29: 24 | C29: 2.16 | E29: 49 | F29: 0.38 | H29: 5 and above | I29: =COUNTIF($T$6:$T$55,">=5") -> 1 | T29: =C29 -> 2.16
B30: 25 | C30: 0.05 | E30: 50 | F30: 0.48 | T30: =C30 -> 0.05
T31: =F6 -> 0.04
B32: Source: Pem-Sim Kelas E.pdf, pp. 1-2 (embedded data image). Sample statistics use n - 1; quartiles use Excel QUARTILE inclusive method. | T32: =F7 -> 1.49
B33: Several values tie for mode: 0.26, 0.36, 0.53, 0.80, and 2.03 min. The MODE cell displays one tied value. | T33: =F8 -> 0.66
T34: =F9 -> 2.03
T35: =F10 -> 1
T36: =F11 -> 0.39
T37: =F12 -> 0.34
T38: =F13 -> 0.01
T39: =F14 -> 0.1
T40: =F15 -> 1.1
T41: =F16 -> 0.24
T42: =F17 -> 0.26
...

Sheet 2 Chi Square
B1: 2 Chi-square goodness-of-fit
B2: H0: recording time follows an exponential distribution | k = 6 | alpha = 0.05
B6: Class | C6: Lower (min) | D6: Upper (min) | E6: Observed O | F6: Expected E | G6: (O-E)^2/E | I6: Test parameter | J6: Value
B7: 1 | C7: 0 | D7: =-$J$9*LN(1-B7/$J$7) -> 0.2198798 | E7: =COUNTIFS('2 Time Data'!$T$6:$T$55,">="&C7,'2 Time Data'!$T$6:$T$55,"<"&D7) -> 8 | F7: =$J$8/$J$7 -> 8.3333333 | G7: =(E7-F7)^2/F7 -> 0.013333333 | I7: Classes k | J7: 6
B8: 2 | C8: =D7 -> 0.2198798 | D8: =-$J$9*LN(1-B8/$J$7) -> 0.48899092 | E8: =COUNTIFS('2 Time Data'!$T$6:$T$55,">="&C8,'2 Time Data'!$T$6:$T$55,"<"&D8) -> 11 | F8: =$J$8/$J$7 -> 8.3333333 | G8: =(E8-F8)^2/F8 -> 0.85333333 | I8: Sample size n | J8: ='2 Time Data'!I6 -> 50
B9: 3 | C9: =D8 -> 0.48899092 | D9: =-$J$9*LN(1-B9/$J$7) -> 0.8359355 | E9: =COUNTIFS('2 Time Data'!$T$6:$T$55,">="&C9,'2 Time Data'!$T$6:$T$55,"<"&D9) -> 9 | F9: =$J$8/$J$7 -> 8.3333333 | G9: =(E9-F9)^2/F9 -> 0.053333333 | I9: Estimated mean | J9: ='2 Time Data'!I8 -> 1.206
B10: 4 | C10: =D9 -> 0.8359355 | D10: =-$J$9*LN(1-B10/$J$7) -> 1.3249264 | E10: =COUNTIFS('2 Time Data'!$T$6:$T$55,">="&C10,'2 Time Data'!$T$6:$T$55,"<"&D10) -> 5 | F10: =$J$8/$J$7 -> 8.3333333 | G10: =(E10-F10)^2/F10 -> 1.3333333 | I10: Rate lambda = 1/mean | J10: =1/J9 -> 0.8291874
B11: 5 | C11: =D10 -> 1.3249264 | D11: =-$J$9*LN(1-B11/$J$7) -> 2.1608619 | E11: =COUNTIFS('2 Time Data'!$T$6:$T$55,">="&C11,'2 Time Data'!$T$6:$T$55,"<"&D11) -> 10 | F11: =$J$8/$J$7 -> 8.3333333 | G11: =(E11-F11)^2/F11 -> 0.33333333 | I11: Degrees of freedom | J11: =J7-1-1 -> 4
B12: 6 | C12: =D11 -> 2.1608619 | D12: infinity | E12: =COUNTIF('2 Time Data'!$T$6:$T$55,">="&C12) -> 7 | F12: =$J$8/$J$7 -> 8.3333333 | G12: =(E12-F12)^2/F12 -> 0.21333333 | I12: Chi-square statistic | J12: =G13 -> 2.8
B13: Total | E13: =SUM(E7:E12) -> 50 | F13: =SUM(F7:F12) -> 50 | G13: =SUM(G7:G12) -> 2.8 | I13: Critical value (5%) | J13: =CHIINV(0.05,J11) -> 9.487729
I14: p-value | J14: =CHIDIST(J12,J11) -> 0.59183271
I15: Decision | J15: =IF(J12>J13,"Reject H0","Do not reject H0") -> Do not reject H0
B17: Class boundaries are fitted exponential quantiles: x_i = -mean * LN(1 - i/6), i = 1,...,5. Each class has expected frequency 50/6 = 8.33, satisfying the usual chi-square minimum of 5.
B20: One parameter (the mean) is estimated from the same sample, so df = 6 - 1 - 1 = 4. A non-rejection means the exponential model is plausible for these data; it does not prove the model is true.
B25: Data: Pem-Sim Kelas E.pdf, p. 2. Method: Law, Simulation Modeling and Analysis, 5th ed., ch. 6; F(x) = 1 - EXP(-x/mean).
